Traceback (most recent call last):
  File "D:\Utilisateurs\rouxemi\AppData\Local\anaconda3\Lib\site-packages\jupyter_cache\executors\utils.py", line 58, in single_nb_execution
    executenb(
  File "D:\Utilisateurs\rouxemi\AppData\Local\anaconda3\Lib\site-packages\nbclient\client.py", line 1204, in execute
    return NotebookClient(nb=nb, resources=resources, km=km, **kwargs).execute()
           ^^^^^^^^^^^^^^^^^^^^^^^^^^^^^^^^^^^^^^^^^^^^^^^^^^^^^^^^^^^^^^^^^^^^^
  File "D:\Utilisateurs\rouxemi\AppData\Local\anaconda3\Lib\site-packages\nbclient\util.py", line 84, in wrapped
    return just_run(coro(*args, **kwargs))
           ^^^^^^^^^^^^^^^^^^^^^^^^^^^^^^^
  File "D:\Utilisateurs\rouxemi\AppData\Local\anaconda3\Lib\site-packages\nbclient\util.py", line 62, in just_run
    return loop.run_until_complete(coro)
           ^^^^^^^^^^^^^^^^^^^^^^^^^^^^^
  File "D:\Utilisateurs\rouxemi\AppData\Local\anaconda3\Lib\asyncio\base_events.py", line 653, in run_until_complete
    return future.result()
           ^^^^^^^^^^^^^^^
  File "D:\Utilisateurs\rouxemi\AppData\Local\anaconda3\Lib\site-packages\nbclient\client.py", line 663, in async_execute
    await self.async_execute_cell(
  File "D:\Utilisateurs\rouxemi\AppData\Local\anaconda3\Lib\site-packages\nbclient\client.py", line 965, in async_execute_cell
    await self._check_raise_for_error(cell, cell_index, exec_reply)
  File "D:\Utilisateurs\rouxemi\AppData\Local\anaconda3\Lib\site-packages\nbclient\client.py", line 862, in _check_raise_for_error
    raise CellExecutionError.from_cell_and_msg(cell, exec_reply_content)
nbclient.exceptions.CellExecutionError: An error occurred while executing the following cell:
------------------
im = Image.open(path)
Nc, Nl = im.size
im = im.resize((Nc // 2, Nl // 2), Image.ANTIALIAS)
fig, ax = plt.subplots()
ax.axis("off")
plt.imshow(im)
plt.show()
------------------

[1;31m---------------------------------------------------------------------------[0m
[1;31mAttributeError[0m                            Traceback (most recent call last)
Cell [1;32mIn[3], line 3[0m
[0;32m      1[0m im [38;5;241m=[39m Image[38;5;241m.[39mopen(path)
[0;32m      2[0m Nc, Nl [38;5;241m=[39m im[38;5;241m.[39msize
[1;32m----> 3[0m im [38;5;241m=[39m im[38;5;241m.[39mresize((Nc [38;5;241m/[39m[38;5;241m/[39m [38;5;241m2[39m, Nl [38;5;241m/[39m[38;5;241m/[39m [38;5;241m2[39m), Image[38;5;241m.[39mANTIALIAS)
[0;32m      4[0m fig, ax [38;5;241m=[39m plt[38;5;241m.[39msubplots()
[0;32m      5[0m ax[38;5;241m.[39maxis([38;5;124m"[39m[38;5;124moff[39m[38;5;124m"[39m)

[1;31mAttributeError[0m: module 'PIL.Image' has no attribute 'ANTIALIAS'
AttributeError: module 'PIL.Image' has no attribute 'ANTIALIAS'

