Traceback (most recent call last):
  File "C:\ProgramData\Anaconda3\envs\JB-env\lib\site-packages\jupyter_cache\executors\utils.py", line 56, in single_nb_execution
    record_timing=False,
  File "C:\ProgramData\Anaconda3\envs\JB-env\lib\site-packages\nbclient\client.py", line 1085, in execute
    return NotebookClient(nb=nb, resources=resources, km=km, **kwargs).execute()
  File "C:\ProgramData\Anaconda3\envs\JB-env\lib\site-packages\nbclient\util.py", line 84, in wrapped
    return just_run(coro(*args, **kwargs))
  File "C:\ProgramData\Anaconda3\envs\JB-env\lib\site-packages\nbclient\util.py", line 62, in just_run
    return loop.run_until_complete(coro)
  File "C:\ProgramData\Anaconda3\envs\JB-env\lib\asyncio\base_events.py", line 587, in run_until_complete
    return future.result()
  File "C:\ProgramData\Anaconda3\envs\JB-env\lib\site-packages\nbclient\client.py", line 552, in async_execute
    cell, index, execution_count=self.code_cells_executed + 1
  File "C:\ProgramData\Anaconda3\envs\JB-env\lib\site-packages\nbclient\client.py", line 846, in async_execute_cell
    self._check_raise_for_error(cell, exec_reply)
  File "C:\ProgramData\Anaconda3\envs\JB-env\lib\site-packages\nbclient\client.py", line 748, in _check_raise_for_error
    raise CellExecutionError.from_cell_and_msg(cell, exec_reply_content)
nbclient.exceptions.CellExecutionError: An error occurred while executing the following cell:
------------------
my_agent(snake.sensors())
------------------

[1;31m---------------------------------------------------------------------------[0m
[1;31mNameError[0m                                 Traceback (most recent call last)
[1;32mC:\Temp\ipykernel_5796\2741160943.py[0m in [0;36m<module>[1;34m[0m
[1;32m----> 1[1;33m [0mmy_agent[0m[1;33m([0m[0msnake[0m[1;33m.[0m[0msensors[0m[1;33m([0m[1;33m)[0m[1;33m)[0m[1;33m[0m[1;33m[0m[0m
[0m
[1;31mNameError[0m: name 'my_agent' is not defined
NameError: name 'my_agent' is not defined

