Traceback (most recent call last):
  File "C:\ProgramData\Anaconda3\envs\JB-env\lib\site-packages\jupyter_cache\executors\utils.py", line 56, in single_nb_execution
    record_timing=False,
  File "C:\ProgramData\Anaconda3\envs\JB-env\lib\site-packages\nbclient\client.py", line 1085, in execute
    return NotebookClient(nb=nb, resources=resources, km=km, **kwargs).execute()
  File "C:\ProgramData\Anaconda3\envs\JB-env\lib\site-packages\nbclient\util.py", line 84, in wrapped
    return just_run(coro(*args, **kwargs))
  File "C:\ProgramData\Anaconda3\envs\JB-env\lib\site-packages\nbclient\util.py", line 62, in just_run
    return loop.run_until_complete(coro)
  File "C:\ProgramData\Anaconda3\envs\JB-env\lib\asyncio\base_events.py", line 587, in run_until_complete
    return future.result()
  File "C:\ProgramData\Anaconda3\envs\JB-env\lib\site-packages\nbclient\client.py", line 552, in async_execute
    cell, index, execution_count=self.code_cells_executed + 1
  File "C:\ProgramData\Anaconda3\envs\JB-env\lib\site-packages\nbclient\client.py", line 846, in async_execute_cell
    self._check_raise_for_error(cell, exec_reply)
  File "C:\ProgramData\Anaconda3\envs\JB-env\lib\site-packages\nbclient\client.py", line 748, in _check_raise_for_error
    raise CellExecutionError.from_cell_and_msg(cell, exec_reply_content)
nbclient.exceptions.CellExecutionError: An error occurred while executing the following cell:
------------------
X = np.array([[0, 0], [20, 0], [25, 12], [30, 10], [50, 20]])

dist = np.linalg.norm(np.diff(X, axis=0), axis=1)
center = X[:-1] + np.diff(X, axis=0) / 2

np.inter2d

Speed = np.array([5, 4, 1, 5])

t = dist / Speed
t_total = t.sum()

plt.figure()
plt.plot(X[:, 0], X[:, 1], ":o")
plt.plot(center[:, 0], center[:, 1], "xr")
plt.imshow(world)
------------------

[1;31m---------------------------------------------------------------------------[0m
[1;31mAttributeError[0m                            Traceback (most recent call last)
[1;32mC:\Temp\ipykernel_5060\48442479.py[0m in [0;36m<module>[1;34m[0m
[0;32m      4[0m [0mcenter[0m [1;33m=[0m [0mX[0m[1;33m[[0m[1;33m:[0m[1;33m-[0m[1;36m1[0m[1;33m][0m [1;33m+[0m [0mnp[0m[1;33m.[0m[0mdiff[0m[1;33m([0m[0mX[0m[1;33m,[0m [0maxis[0m[1;33m=[0m[1;36m0[0m[1;33m)[0m [1;33m/[0m [1;36m2[0m[1;33m[0m[1;33m[0m[0m
[0;32m      5[0m [1;33m[0m[0m
[1;32m----> 6[1;33m [0mnp[0m[1;33m.[0m[0minter2d[0m[1;33m[0m[1;33m[0m[0m
[0m[0;32m      7[0m [1;33m[0m[0m
[0;32m      8[0m [0mSpeed[0m [1;33m=[0m [0mnp[0m[1;33m.[0m[0marray[0m[1;33m([0m[1;33m[[0m[1;36m5[0m[1;33m,[0m [1;36m4[0m[1;33m,[0m [1;36m1[0m[1;33m,[0m [1;36m5[0m[1;33m][0m[1;33m)[0m[1;33m[0m[1;33m[0m[0m

[1;32mC:\ProgramData\Anaconda3\envs\JB-env\lib\site-packages\numpy\__init__.py[0m in [0;36m__getattr__[1;34m(attr)[0m
[0;32m    312[0m [1;33m[0m[0m
[0;32m    313[0m             raise AttributeError("module {!r} has no attribute "
[1;32m--> 314[1;33m                                  "{!r}".format(__name__, attr))
[0m[0;32m    315[0m [1;33m[0m[0m
[0;32m    316[0m         [1;32mdef[0m [0m__dir__[0m[1;33m([0m[1;33m)[0m[1;33m:[0m[1;33m[0m[1;33m[0m[0m

[1;31mAttributeError[0m: module 'numpy' has no attribute 'inter2d'
AttributeError: module 'numpy' has no attribute 'inter2d'

