Traceback (most recent call last):
  File "/opt/conda/envs/science/lib/python3.10/site-packages/jupyter_cache/executors/utils.py", line 58, in single_nb_execution
    executenb(
  File "/opt/conda/envs/science/lib/python3.10/site-packages/nbclient/client.py", line 1305, in execute
    return NotebookClient(nb=nb, resources=resources, km=km, **kwargs).execute()
  File "/opt/conda/envs/science/lib/python3.10/site-packages/jupyter_core/utils/__init__.py", line 165, in wrapped
    return loop.run_until_complete(inner)
  File "/opt/conda/envs/science/lib/python3.10/asyncio/base_events.py", line 649, in run_until_complete
    return future.result()
  File "/opt/conda/envs/science/lib/python3.10/site-packages/nbclient/client.py", line 705, in async_execute
    await self.async_execute_cell(
  File "/opt/conda/envs/science/lib/python3.10/site-packages/nbclient/client.py", line 1058, in async_execute_cell
    await self._check_raise_for_error(cell, cell_index, exec_reply)
  File "/opt/conda/envs/science/lib/python3.10/site-packages/nbclient/client.py", line 914, in _check_raise_for_error
    raise CellExecutionError.from_cell_and_msg(cell, exec_reply_content)
nbclient.exceptions.CellExecutionError: An error occurred while executing the following cell:
------------------
im = Image.open(path)
Nc, Nl = im.size
im = im.resize((Nc // 4, Nl // 4), Image.ANTIALIAS)
fig, ax = plt.subplots()
# ax.axis("off")
plt.imshow(im)
plt.colorbar()
plt.show()
------------------


[0;31m---------------------------------------------------------------------------[0m
[0;31mAttributeError[0m                            Traceback (most recent call last)
Cell [0;32mIn[3], line 3[0m
[1;32m      1[0m im [38;5;241m=[39m Image[38;5;241m.[39mopen(path)
[1;32m      2[0m Nc, Nl [38;5;241m=[39m im[38;5;241m.[39msize
[0;32m----> 3[0m im [38;5;241m=[39m im[38;5;241m.[39mresize((Nc [38;5;241m/[39m[38;5;241m/[39m [38;5;241m4[39m, Nl [38;5;241m/[39m[38;5;241m/[39m [38;5;241m4[39m), [43mImage[49m[38;5;241;43m.[39;49m[43mANTIALIAS[49m)
[1;32m      4[0m fig, ax [38;5;241m=[39m plt[38;5;241m.[39msubplots()
[1;32m      5[0m [38;5;66;03m# ax.axis("off")[39;00m

[0;31mAttributeError[0m: module 'PIL.Image' has no attribute 'ANTIALIAS'

